<?xml version="1.0" ?>

<robot name="ursrh" xmlns:controller="http://playerstage.sourceforge.net/gazebo/xmlschema/#controller" xmlns:interface="http://playerstage.sourceforge.net/gazebo/xmlschema/#interface" xmlns:sensor="http://playerstage.sourceforge.net/gazebo/xmlschema/#sensor">
  <link name="world"/>
  <!-- links: main serial chain -->
  <link name="base_link"/>
  <link name="base_link_inertia">
    <visual>
      <origin rpy="0 0 3.141592653589793" xyz="0 0 0"/>
      <geometry>
        <mesh filename="package://ur_description/meshes/ur10/visual/base.dae"/>
      </geometry>
      <material name="LightGrey">
        <color rgba="0.7 0.7 0.7 1.0"/>
      </material>
    </visual>
    <collision>
      <origin rpy="0 0 3.141592653589793" xyz="0 0 0"/>
      <geometry>
        <mesh filename="package://ur_description/meshes/ur10/collision/base.stl"/>
      </geometry>
    </collision>
    <inertial>
      <mass value="4.0"/>
      <origin rpy="0 0 0" xyz="0 0 0"/>
      <inertia ixx="0.0061063308908" ixy="0.0" ixz="0.0" iyy="0.0061063308908" iyz="0.0" izz="0.01125"/>
    </inertial>
  </link>
  <link name="shoulder_link">
    <visual>
      <origin rpy="0 0 3.141592653589793" xyz="0 0 0"/>
      <geometry>
        <mesh filename="package://ur_description/meshes/ur10/visual/shoulder.dae"/>
      </geometry>
      <material name="LightGrey">
        <color rgba="0.7 0.7 0.7 1.0"/>
      </material>
    </visual>
    <collision>
      <origin rpy="0 0 3.141592653589793" xyz="0 0 0"/>
      <geometry>
        <mesh filename="package://ur_description/meshes/ur10/collision/shoulder.stl"/>
      </geometry>
    </collision>
    <inertial>
      <mass value="7.778"/>
      <origin rpy="0 0 0" xyz="0 0 0"/>
      <inertia ixx="0.03147431257693659" ixy="0.0" ixz="0.0" iyy="0.03147431257693659" iyz="0.0" izz="0.021875624999999996"/>
    </inertial>
  </link>
  <link name="upper_arm_link">
    <visual>
      <origin rpy="1.5707963267948966 0 -1.5707963267948966" xyz="0 0 0.220941"/>
      <geometry>
        <mesh filename="package://ur_description/meshes/ur10/visual/upperarm.dae"/>
      </geometry>
      <material name="LightGrey">
        <color rgba="0.7 0.7 0.7 1.0"/>
      </material>
    </visual>
    <collision>
      <origin rpy="1.5707963267948966 0 -1.5707963267948966" xyz="0 0 0.220941"/>
      <geometry>
        <mesh filename="package://ur_description/meshes/ur10/collision/upperarm.stl"/>
      </geometry>
    </collision>
    <inertial>
      <mass value="12.93"/>
      <origin rpy="0 1.5707963267948966 0" xyz="-0.306 0.0 0.175"/>
      <inertia ixx="0.42175380379841093" ixy="0.0" ixz="0.0" iyy="0.42175380379841093" iyz="0.0" izz="0.03636562499999999"/>
    </inertial>
  </link>
  <link name="forearm_link">
    <visual>
      <origin rpy="1.5707963267948966 0 -1.5707963267948966" xyz="0 0 0.049042"/>
      <geometry>
        <mesh filename="package://ur_description/meshes/ur10/visual/forearm.dae"/>
      </geometry>
      <material name="LightGrey">
        <color rgba="0.7 0.7 0.7 1.0"/>
      </material>
    </visual>
    <collision>
      <origin rpy="1.5707963267948966 0 -1.5707963267948966" xyz="0 0 0.049042"/>
      <geometry>
        <mesh filename="package://ur_description/meshes/ur10/collision/forearm.stl"/>
      </geometry>
    </collision>
    <inertial>
      <mass value="3.87"/>
      <origin rpy="0 1.5707963267948966 0" xyz="-0.28615 0.0 0.049042"/>
      <inertia ixx="0.11106969409710458" ixy="0.0" ixz="0.0" iyy="0.11106969409710458" iyz="0.0" izz="0.010884375"/>
    </inertial>
  </link>
  <link name="wrist_1_link">
    <visual>
      <!-- TODO: Move this to a parameter -->
      <origin rpy="1.5707963267948966 0 0" xyz="0 0 -0.1149"/>
      <geometry>
        <mesh filename="package://ur_description/meshes/ur10/visual/wrist1.dae"/>
      </geometry>
      <material name="LightGrey">
        <color rgba="0.7 0.7 0.7 1.0"/>
      </material>
    </visual>
    <collision>
      <origin rpy="1.5707963267948966 0 0" xyz="0 0 -0.1149"/>
      <geometry>
        <mesh filename="package://ur_description/meshes/ur10/collision/wrist1.stl"/>
      </geometry>
    </collision>
    <inertial>
      <mass value="1.96"/>
      <origin rpy="0 0 0" xyz="0 0 0"/>
      <inertia ixx="0.005108247956699999" ixy="0.0" ixz="0.0" iyy="0.005108247956699999" iyz="0.0" izz="0.005512499999999999"/>
    </inertial>
  </link>
  <link name="wrist_2_link">
    <visual>
      <origin rpy="0 0 0" xyz="0 0 -0.1158"/>
      <geometry>
        <mesh filename="package://ur_description/meshes/ur10/visual/wrist2.dae"/>
      </geometry>
      <material name="LightGrey">
        <color rgba="0.7 0.7 0.7 1.0"/>
      </material>
    </visual>
    <collision>
      <origin rpy="0 0 0" xyz="0 0 -0.1158"/>
      <geometry>
        <mesh filename="package://ur_description/meshes/ur10/collision/wrist2.stl"/>
      </geometry>
    </collision>
    <inertial>
      <mass value="1.96"/>
      <origin rpy="0 0 0" xyz="0 0 0"/>
      <inertia ixx="0.0040792483683" ixy="0.0" ixz="0.0" iyy="0.0040792483683" iyz="0.0" izz="0.005512499999999999"/>
    </inertial>
  </link>
  <link name="wrist_3_link">
    <visual>
      <origin rpy="1.5707963267948966 0 0" xyz="0 0 -0.0922"/>
      <geometry>
        <mesh filename="package://ur_description/meshes/ur10/visual/wrist3.dae"/>
      </geometry>
      <material name="LightGrey">
        <color rgba="0.7 0.7 0.7 1.0"/>
      </material>
    </visual>
    <collision>
      <origin rpy="1.5707963267948966 0 0" xyz="0 0 -0.0922"/>
      <geometry>
        <mesh filename="package://ur_description/meshes/ur10/collision/wrist3.stl"/>
      </geometry>
    </collision>
    <inertial>
      <mass value="0.202"/>
      <origin rpy="0 0 0" xyz="0.0 0.0 -0.01525"/>
      <inertia ixx="0.00011792166116465" ixy="0.0" ixz="0.0" iyy="0.00011792166116465" iyz="0.0" izz="0.00020452500000000002"/>
    </inertial>
  </link>
  <!-- joints: main serial chain -->
  <joint name="base_link-base_link_inertia" type="fixed">
    <parent link="base_link"/>
    <child link="base_link_inertia"/>
    <!-- 'base_link' is REP-103 aligned (so X+ forward), while the internal
           frames of the robot/controller have X+ pointing backwards.
           Use the joint between 'base_link' and 'base_link_inertia' (a dummy
           link/frame) to introduce the necessary rotation over Z (of pi rad).
      -->
    <origin rpy="0 0 3.141592653589793" xyz="0 0 0"/>
  </joint>
  <joint name="shoulder_pan_joint" type="revolute">
    <parent link="base_link_inertia"/>
    <child link="shoulder_link"/>
    <origin rpy="0 0 0" xyz="0 0 0.1273"/>
    <axis xyz="0 0 1"/>
    <limit effort="330.0" lower="-6.283185307179586" upper="6.283185307179586" velocity="2.0943951023931953"/>
    <dynamics damping="0" friction="0"/>
  </joint>
  <joint name="shoulder_lift_joint" type="revolute">
    <parent link="shoulder_link"/>
    <child link="upper_arm_link"/>
    <origin rpy="1.570796327 0 0" xyz="0 0 0"/>
    <axis xyz="0 0 1"/>
    <limit effort="330.0" lower="-6.283185307179586" upper="6.283185307179586" velocity="2.0943951023931953"/>
    <dynamics damping="0" friction="0"/>
  </joint>
  <joint name="elbow_joint" type="revolute">
    <parent link="upper_arm_link"/>
    <child link="forearm_link"/>
    <origin rpy="0 0 0" xyz="-0.612 0 0"/>
    <axis xyz="0 0 1"/>
    <limit effort="150.0" lower="-3.141592653589793" upper="3.141592653589793" velocity="3.141592653589793"/>
    <dynamics damping="0" friction="0"/>
  </joint>
  <joint name="wrist_1_joint" type="revolute">
    <parent link="forearm_link"/>
    <child link="wrist_1_link"/>
    <origin rpy="0 0 0" xyz="-0.5723 0 0.163941"/>
    <axis xyz="0 0 1"/>
    <limit effort="56.0" lower="-6.283185307179586" upper="6.283185307179586" velocity="3.141592653589793"/>
    <dynamics damping="0" friction="0"/>
  </joint>
  <joint name="wrist_2_joint" type="revolute">
    <parent link="wrist_1_link"/>
    <child link="wrist_2_link"/>
    <origin rpy="1.570796327 0 0" xyz="0 -0.1157 -2.373046667922381e-11"/>
    <axis xyz="0 0 1"/>
    <limit effort="56.0" lower="-6.283185307179586" upper="6.283185307179586" velocity="3.141592653589793"/>
    <dynamics damping="0" friction="0"/>
  </joint>
  <joint name="wrist_3_joint" type="revolute">
    <parent link="wrist_2_link"/>
    <child link="wrist_3_link"/>
    <origin rpy="1.570796326589793 3.141592653589793 3.141592653589793" xyz="0 0.0922 -1.891053610911353e-11"/>
    <axis xyz="0 0 1"/>
    <limit effort="56.0" lower="-6.283185307179586" upper="6.283185307179586" velocity="3.141592653589793"/>
    <dynamics damping="0" friction="0"/>
  </joint>
  <!-- ROS-Industrial 'base' frame: base_link to UR 'Base' Coordinates transform -->
  <link name="base"/>
  <joint name="base_link-base_fixed_joint" type="fixed">
    <!-- Note the rotation over Z of pi radians: as base_link is REP-103
           aligned (ie: has X+ forward, Y+ left and Z+ up), this is needed
           to correctly align 'base' with the 'Base' coordinate system of
           the UR controller.
      -->
    <origin rpy="0 0 3.141592653589793" xyz="0 0 0"/>
    <parent link="base_link"/>
    <child link="base"/>
  </joint>
  <!-- ROS-Industrial 'flange' frame: attachment point for EEF models -->
  <link name="flange"/>
  <joint name="wrist_3-flange" type="fixed">
    <parent link="wrist_3_link"/>
    <child link="flange"/>
    <origin rpy="0 -1.5707963267948966 -1.5707963267948966" xyz="0 0 0"/>
  </joint>
  <!-- ROS-Industrial 'tool0' frame: all-zeros tool frame -->
  <link name="tool0"/>
  <joint name="flange-tool0" type="fixed">
    <!-- default toolframe: X+ left, Y+ up, Z+ front -->
    <origin rpy="1.5707963267948966 0 1.5707963267948966" xyz="0 0 0"/>
    <parent link="flange"/>
    <child link="tool0"/>
  </joint>
  <material name="Blue">
    <color rgba="0.0 0.0 0.8 1.0"/>
  </material>
  <material name="Green">
    <color rgba="0.0 0.8 0.0 1.0"/>
  </material>
  <material name="BiotacGreen">
    <color rgba="0.31 0.85 0.42 1.0"/>
  </material>
  <material name="Grey">
    <color rgba="0.2 0.2 0.2 1.0"/>
  </material>
  <material name="LightGrey">
    <color rgba="0.6 0.6 0.6 1.0"/>
  </material>
  <material name="Red">
    <color rgba="0.8 0.0 0.0 1.0"/>
  </material>
  <material name="White">
    <color rgba="1.0 1.0 1.0 1.0"/>
  </material>
  
  <link name="forearm">
    <inertial>
      <origin rpy="0 0 0" xyz="0 0 0.09"/>
      <mass value="3.0"/>
      <inertia ixx="0.0138" ixy="0.0" ixz="0.0" iyy="0.0138" iyz="0.0" izz="0.00744"/>
    </inertial>
    <visual>
      <origin rpy="0 0 0" xyz="0 0 0.006"/>
      <geometry name="forearm_visual">
        <mesh filename="package://sr_description/meshes/components/forearm/forearm_E3M5.dae" scale="0.001 0.001 0.001"/>
      </geometry>
      <material name="light_grey">
        <color rgba="0.90000 0.90000 0.90000 1.0"/>
      </material>
    </visual>
    <collision>
      <origin rpy="0 0 0" xyz="0 0 0.006"/>
      <geometry name="forearm_collision">
        <mesh filename="package://sr_description/meshes/components/forearm/forearm_collision_E3M5.dae" scale="0.001 0.001 0.001"/>
      </geometry>
    </collision>
    <!-- wrist mount -->
    <collision>
      <origin rpy="0 0.78 0" xyz="0 -0.01 0.187"/>
      <geometry>
        <box size="0.07 0.07 0.07"/>
      </geometry>
    </collision>
    <visual>
      <origin rpy="0 0 0" xyz="0 0 0"/>
      <geometry name="mounting_plate">
        <mesh filename="package://sr_description/meshes/components/mounting_plate/mounting_plate_E3M5.dae" scale="0.001 0.001 0.001"/>
      </geometry>
    </visual>
    <collision>
      <origin rpy="0 0 0" xyz="0 0 0.002"/>
      <geometry>
        <cylinder length="0.008" radius="0.0675"/>
      </geometry>
    </collision>
    <!-- TODO: Make a decision on whether to add the connector or not -->
    <!--visual>
        <origin rpy="0 -1.57 -1.57" xyz="0.0 0.067 0.0045"/>
        <geometry name="${prefix}cable_extr_visualisation">
          <mesh filename="package://sr_description/meshes/components/cable_connector/cable_connector_base_${hand_version}.dae" scale="0.001 0.001 0.001" />
        </geometry>
      </visual-->
  </link>

  <link name="wrist">
    <inertial>
      <origin rpy="0 0 0" xyz="0 0 0.029"/>
      <mass value="0.1"/>
      <inertia ixx="0.000035" ixy="0.0" ixz="0.0" iyy="0.000064" iyz="0.0" izz="0.0000438"/>
    </inertial>
    <visual>
      <origin rpy="0 0 0" xyz="0 0 0"/>
      <geometry name="wrist_visual">
        <mesh filename="package://sr_description/meshes/components/wrist/wrist_E3M5.dae" scale="0.001 0.001 0.001"/>
      </geometry>
      <material name="LightGrey"/>
    </visual>
    <collision>
      <origin rpy="1.5708 1.5708 0" xyz="0 0 0"/>
      <geometry name="wrist_collision_geom">
        <cylinder length="0.030" radius="0.0135"/>
      </geometry>
    </collision>
    <collision>
      <origin rpy="0 1.5708 0" xyz="-0.026 0 0.034"/>
      <geometry>
        <cylinder length="0.010" radius="0.011"/>
      </geometry>
    </collision>
    <collision>
      <origin rpy="0 1.5708 0" xyz="0.031 0 0.034"/>
      <geometry>
        <cylinder length="0.010" radius="0.011"/>
      </geometry>
    </collision>
    <collision>
      <origin rpy="0 0.7854 0" xyz="-0.021 0 0.011"/>
      <geometry>
        <box size="0.027 0.018 0.010"/>
      </geometry>
    </collision>
    <collision>
      <origin rpy="0 -0.7854 0" xyz="0.026 0 0.010"/>
      <geometry>
        <box size="0.027 0.018 0.010"/>
      </geometry>
    </collision>
  </link>
  
  <joint name="WRJ2" type="revolute">
    <parent link="forearm"/>
    <child link="wrist"/>
    <origin rpy="0 0 0" xyz="0 -0.010 0.21301"/>
    <axis xyz="0 1 0"/>
    <limit effort="10" lower="-0.5235987755982988" upper="0.17453292519943295" velocity="2.0"/>
    <dynamics damping="0.1"/>
  </joint>
 
  <link name="palm">
    <inertial>
      <origin rpy="0 0 0" xyz="0 0 0.035"/>
      <mass value="0.3"/>
      <inertia ixx="0.0003581" ixy="0.0" ixz="0.0" iyy="0.0005287" iyz="0.0" izz="0.000191"/>
    </inertial>
    <visual>
      <origin rpy="0 0 0" xyz="0 0 0"/>
      <geometry name="palm_visual">
        <mesh filename="package://sr_description/meshes/components/palm/palm_E3M5.dae" scale="0.001 0.001 0.001"/>
      </geometry>
      <material name="Grey"/>
    </visual>
    <collision>
      <origin rpy="0 0 0" xyz="0.011 0.0085 0.038"/>
      <geometry name="palm_collision_geom">
        <box size="0.062 0.007 0.098"/>
      </geometry>
    </collision>
    <collision>
      <origin rpy="0 0 0" xyz="-0.002 -0.0035 0.038"/>
      <geometry>
        <box size="0.036 0.017 0.098"/>
      </geometry>
    </collision>
    <!-- palm complement below first finger -->
    <collision>
      <origin rpy="0 0 0" xyz="0.029 -0.0035 0.082"/>
      <geometry>
        <box size="0.026 0.017 0.010"/>
      </geometry>
    </collision>
    <collision>
      <origin rpy="0.2 0 0.25" xyz="0.0265 -0.001 0.070"/>
      <geometry>
        <box size="0.026 0.014 0.018"/>
      </geometry>
    </collision>
    <!-- thumb pulp side -->
    <collision>
      <origin rpy="0 0 0" xyz="0.0315 -0.0085 0.001"/>
      <geometry>
        <box size="0.021 0.027 0.024"/>
      </geometry>
    </collision>
    <!-- thumb pulp central -->
    <collision>
      <origin rpy="0 0 -0.48" xyz="0.0125 -0.015 0.009"/>
      <geometry>
        <box size="0.022 0.005 0.040"/>
      </geometry>
    </collision>
    <!-- above middle finger-->
    <collision>
      <origin rpy="0 0 0" xyz="0.011 0 0.089"/>
      <geometry>
        <box size="0.018 0.024 0.004"/>
      </geometry>
    </collision>
    <!-- metacarpal side-->
    <collision>
      <origin rpy="0 0 0" xyz="-0.03 0 0.009"/>
      <geometry>
        <box size="0.020 0.024 0.040"/>
      </geometry>
    </collision>
  </link>
  <joint name="ee_fixed_joint" type="fixed">
    <parent link="palm"/>
    <child link="manipulator"/>
    <origin rpy="0.0 0.0 0.0" xyz="0.0 0.0 0.05"/>
  </joint>
  <link name="manipulator"/>
  <joint name="WRJ1" type="revolute">
    <parent link="wrist"/>
    <child link="palm"/>
    <origin rpy="0 0 0" xyz="0 0 0.034"/>
    <axis xyz="1 0 0"/>
    <limit effort="30" lower="-0.6981317007977318" upper="0.4886921905584123" velocity="2.0"/>
    <dynamics damping="0.1"/>
  </joint>

  <link name="imu"/>
  <joint name="palm_to_imu" type="fixed">
    <parent link="palm"/>
    <child link="imu"/>
    <origin rpy="-1.5707963 3.141592 0.0" xyz="0.01785 0.00765 0.049125"/>
  </joint>

  <link name="ffknuckle">
    <inertial>
      <origin rpy="0 0 0" xyz="0 0 0"/>
      <mass value="0.008"/>
      <inertia ixx="0.00000026" ixy="0.0" ixz="0.0" iyy="0.00000026" iyz="0.0" izz="0.00000032"/>
    </inertial>
    <visual>
      <origin rpy="0 0 0" xyz="0 0 0.0005"/>
      <geometry name="ffknuckle_visual">
        <mesh filename="package://sr_description/meshes/components/f_knuckle/f_knuckle_E3M5.dae" scale="0.001 0.001 0.001"/>
      </geometry>
      <material name="LightGrey"/>
    </visual>
    <collision>
      <origin rpy="0 1.5708 0" xyz="0 0 0"/>
      <geometry name="ffknuckle_collision_geom">
        <cylinder length="0.014" radius="0.007"/>
      </geometry>
    </collision>
  </link>
  <joint name="FFJ4" type="revolute">
    <parent link="palm"/>
    <child link="ffknuckle"/>
    <!--<origin xyz="0.033 0 0.095" rpy="0 0 0" />-->
    <origin rpy="0 0 0" xyz="0.033 0 0.095"/>
    <axis xyz="0 -1 0"/>
    <limit effort="2" lower="-0.3490658503988659" upper="0.3490658503988659" velocity="2.0"/>
    <dynamics damping="0.1"/>
  </joint>

  <link name="ffproximal">
    <inertial>
      <mass value="0.030"/>
      <origin xyz="0 0 0.0225"/>
      <inertia ixx="0.0000098" ixy="0.0" ixz="0.0" iyy="0.00001" iyz="0.0" izz="0.0000018"/>
    </inertial>
    <visual>
      <origin rpy="0 0 0" xyz="0 0 0"/>
      <geometry name="ffproximal_visual">
        <mesh filename="package://sr_description/meshes/components/f_proximal/f_proximal_E3M5.dae" scale="0.001 0.001 0.001"/>
      </geometry>
      <material name="Grey"/>
    </visual>
    <collision>
      <origin rpy="0 0 0" xyz="0 0 0.025"/>
      <geometry name="ffproximal_collision_geom">
        <cylinder length="0.040" radius="0.007"/>
      </geometry>
    </collision>
  </link>
  <joint name="FFJ3" type="revolute">
    <parent link="ffknuckle"/>
    <child link="ffproximal"/>
    <origin rpy="0 0 0" xyz="0 0 0"/>
    <axis xyz="1 0 0"/>
    <limit effort="2" lower="-0.2617993877991494" upper="1.5707963267948966" velocity="2.0"/>
    <dynamics damping="0.1"/>
  </joint>
  
  <link name="ffmiddle">
    <inertial>
      <origin rpy="0 0 0" xyz="0 0 0.0125"/>
      <mass value="0.017"/>
      <inertia ixx="0.0000026" ixy="0.0" ixz="0.0" iyy="0.0000027" iyz="0.0" izz="0.00000087"/>
    </inertial>
    <visual>
      <origin rpy="0 0 0" xyz="0 0 0"/>
      <geometry name="ffmiddle_visual">
        <mesh filename="package://sr_description/meshes/components/f_middle/f_middle_E3M5.dae" scale="0.001 0.001 0.001"/>
      </geometry>
      <material name="Grey"/>
    </visual>
    <collision>
      <origin rpy="0 0 0" xyz="0 0 0.0125"/>
      <geometry name="ffmiddle_collision_geom">
        <cylinder length="0.025" radius="0.007"/>
      </geometry>
    </collision>
    <collision>
      <origin rpy="0 0 0" xyz="0 0 0.0"/>
      <geometry>
        <sphere radius="0.007"/>
      </geometry>
    </collision>
    <collision>
      <origin rpy="0 0 0" xyz="0 0 0.025"/>
      <geometry>
        <sphere radius="0.007"/>
      </geometry>
    </collision>
  </link>
  <joint name="FFJ2" type="revolute">
    <parent link="ffproximal"/>
    <child link="ffmiddle"/>
    <origin rpy="0 0 0" xyz="0 0 0.045"/>
    <axis xyz="1 0 0"/>
    <limit effort="2" lower="0" upper="1.5707963267948966" velocity="2.0"/>
    <dynamics damping="0.1"/>
  </joint>

  <link name="ffdistal">
    <inertial>
      <mass value="0.012"/>
      <origin xyz="0 0 0.012"/>
      <inertia ixx="0.00000094" ixy="0.0" ixz="0.0" iyy="0.0000011" iyz="0.0" izz="0.00000053"/>
    </inertial>
    <visual>
      <origin rpy="0 0 0" xyz="0 0 0"/>
      <geometry name="ffdistal_visual">
        <mesh filename="package://sr_description/meshes/components/f_distal/pst/f_distal_pst.dae" scale="0.001 0.001 0.001"/>
      </geometry>
    </visual>
    <collision>
      <origin rpy="0 0 0" xyz="0 0 0"/>
      <geometry name="ffdistal_collision_geom">
        <mesh filename="package://sr_description/meshes/components/f_distal/pst/f_distal_pst.dae" scale="0.001 0.001 0.001"/>
      </geometry>
    </collision>
  </link>
  <joint name="FFJ1" type="revolute">
    <parent link="ffmiddle"/>
    <child link="ffdistal"/>
    <origin rpy="0 0 0" xyz="0 0 0.025"/>
    <axis xyz="1 0 0"/>
    <!-- standard distal joint -->
    <limit effort="2" lower="0" upper="1.5707963267948966" velocity="2.0"/>
    <dynamics damping="0.1"/>
  </joint>
  
  <link name="fftip">
    <inertial>
      <mass value="0.001"/>
      <inertia ixx="0.0" ixy="0.0" ixz="0.0" iyy="0.0" iyz="0.0" izz="0.0"/>
    </inertial>
  </link>
  <joint name="FFtip" type="fixed">
    <parent link="ffdistal"/>
    <child link="fftip"/>
    <origin rpy="0 0 0" xyz="0 0 0.026"/>
  </joint>
 
  <link name="mfknuckle">
    <inertial>
      <origin rpy="0 0 0" xyz="0 0 0"/>
      <mass value="0.008"/>
      <inertia ixx="0.00000026" ixy="0.0" ixz="0.0" iyy="0.00000026" iyz="0.0" izz="0.00000032"/>
    </inertial>
    <visual>
      <origin rpy="0 0 0" xyz="0 0 0.0005"/>
      <geometry name="mfknuckle_visual">
        <mesh filename="package://sr_description/meshes/components/f_knuckle/f_knuckle_E3M5.dae" scale="0.001 0.001 0.001"/>
      </geometry>
      <material name="LightGrey"/>
    </visual>
    <collision>
      <origin rpy="0 1.5708 0" xyz="0 0 0"/>
      <geometry name="mfknuckle_collision_geom">
        <cylinder length="0.014" radius="0.007"/>
      </geometry>
    </collision>
  </link>
  <joint name="MFJ4" type="revolute">
    <parent link="palm"/>
    <child link="mfknuckle"/>
    <!--<origin xyz="0.033 0 0.095" rpy="0 0 0" />-->
    <origin rpy="0 0 0" xyz="0.011 0 0.099"/>
    <axis xyz="0 -1 0"/>
    <limit effort="2" lower="-0.3490658503988659" upper="0.3490658503988659" velocity="2.0"/>
    <dynamics damping="0.1"/>
  </joint>
  
  <link name="mfproximal">
    <inertial>
      <mass value="0.030"/>
      <origin xyz="0 0 0.0225"/>
      <inertia ixx="0.0000098" ixy="0.0" ixz="0.0" iyy="0.00001" iyz="0.0" izz="0.0000018"/>
    </inertial>
    <visual>
      <origin rpy="0 0 0" xyz="0 0 0"/>
      <geometry name="mfproximal_visual">
        <mesh filename="package://sr_description/meshes/components/f_proximal/f_proximal_E3M5.dae" scale="0.001 0.001 0.001"/>
      </geometry>
      <material name="Grey"/>
    </visual>
    <collision>
      <origin rpy="0 0 0" xyz="0 0 0.025"/>
      <geometry name="mfproximal_collision_geom">
        <cylinder length="0.040" radius="0.007"/>
      </geometry>
    </collision>
  </link>
  <joint name="MFJ3" type="revolute">
    <parent link="mfknuckle"/>
    <child link="mfproximal"/>
    <origin rpy="0 0 0" xyz="0 0 0"/>
    <axis xyz="1 0 0"/>
    <limit effort="2" lower="-0.2617993877991494" upper="1.5707963267948966" velocity="2.0"/>
    <dynamics damping="0.1"/>
  </joint>
  
  <link name="mfmiddle">
    <inertial>
      <origin rpy="0 0 0" xyz="0 0 0.0125"/>
      <mass value="0.017"/>
      <inertia ixx="0.0000026" ixy="0.0" ixz="0.0" iyy="0.0000027" iyz="0.0" izz="0.00000087"/>
    </inertial>
    <visual>
      <origin rpy="0 0 0" xyz="0 0 0"/>
      <geometry name="mfmiddle_visual">
        <mesh filename="package://sr_description/meshes/components/f_middle/f_middle_E3M5.dae" scale="0.001 0.001 0.001"/>
      </geometry>
      <material name="Grey"/>
    </visual>
    <collision>
      <origin rpy="0 0 0" xyz="0 0 0.0125"/>
      <geometry name="mfmiddle_collision_geom">
        <cylinder length="0.025" radius="0.007"/>
      </geometry>
    </collision>
    <collision>
      <origin rpy="0 0 0" xyz="0 0 0.0"/>
      <geometry>
        <sphere radius="0.007"/>
      </geometry>
    </collision>
    <collision>
      <origin rpy="0 0 0" xyz="0 0 0.025"/>
      <geometry>
        <sphere radius="0.007"/>
      </geometry>
    </collision>
  </link>
  <joint name="MFJ2" type="revolute">
    <parent link="mfproximal"/>
    <child link="mfmiddle"/>
    <origin rpy="0 0 0" xyz="0 0 0.045"/>
    <axis xyz="1 0 0"/>
    <limit effort="2" lower="0" upper="1.5707963267948966" velocity="2.0"/>
    <dynamics damping="0.1"/>
  </joint>
  
  <link name="mfdistal">
    <inertial>
      <mass value="0.012"/>
      <origin xyz="0 0 0.012"/>
      <inertia ixx="0.00000094" ixy="0.0" ixz="0.0" iyy="0.0000011" iyz="0.0" izz="0.00000053"/>
    </inertial>
    <visual>
      <origin rpy="0 0 0" xyz="0 0 0"/>
      <geometry name="mfdistal_visual">
        <mesh filename="package://sr_description/meshes/components/f_distal/pst/f_distal_pst.dae" scale="0.001 0.001 0.001"/>
      </geometry>
    </visual>
    <collision>
      <origin rpy="0 0 0" xyz="0 0 0"/>
      <geometry name="mfdistal_collision_geom">
        <mesh filename="package://sr_description/meshes/components/f_distal/pst/f_distal_pst.dae" scale="0.001 0.001 0.001"/>
      </geometry>
    </collision>
  </link>
  <joint name="MFJ1" type="revolute">
    <parent link="mfmiddle"/>
    <child link="mfdistal"/>
    <origin rpy="0 0 0" xyz="0 0 0.025"/>
    <axis xyz="1 0 0"/>
    <!-- standard distal joint -->
    <limit effort="2" lower="0" upper="1.5707963267948966" velocity="2.0"/>
    <dynamics damping="0.1"/>
  </joint>
 
  <link name="mftip">
    <inertial>
      <mass value="0.001"/>
      <inertia ixx="0.0" ixy="0.0" ixz="0.0" iyy="0.0" iyz="0.0" izz="0.0"/>
    </inertial>
  </link>
  <joint name="MFtip" type="fixed">
    <parent link="mfdistal"/>
    <child link="mftip"/>
    <origin rpy="0 0 0" xyz="0 0 0.026"/>
  </joint>
  
  <link name="rfknuckle">
    <inertial>
      <origin rpy="0 0 0" xyz="0 0 0"/>
      <mass value="0.008"/>
      <inertia ixx="0.00000026" ixy="0.0" ixz="0.0" iyy="0.00000026" iyz="0.0" izz="0.00000032"/>
    </inertial>
    <visual>
      <origin rpy="0 0 0" xyz="0 0 0.0005"/>
      <geometry name="rfknuckle_visual">
        <mesh filename="package://sr_description/meshes/components/f_knuckle/f_knuckle_E3M5.dae" scale="0.001 0.001 0.001"/>
      </geometry>
      <material name="LightGrey"/>
    </visual>
    <collision>
      <origin rpy="0 1.5708 0" xyz="0 0 0"/>
      <geometry name="rfknuckle_collision_geom">
        <cylinder length="0.014" radius="0.007"/>
      </geometry>
    </collision>
  </link>
  <joint name="RFJ4" type="revolute">
    <parent link="palm"/>
    <child link="rfknuckle"/>
    <!--<origin xyz="0.033 0 0.095" rpy="0 0 0" />-->
    <origin rpy="0 0 0" xyz="-0.011 0 0.095"/>
    <axis xyz="0 1 0"/>
    <limit effort="2" lower="-0.3490658503988659" upper="0.3490658503988659" velocity="2.0"/>
    <dynamics damping="0.1"/>
  </joint>
  
  <link name="rfproximal">
    <inertial>
      <mass value="0.030"/>
      <origin xyz="0 0 0.0225"/>
      <inertia ixx="0.0000098" ixy="0.0" ixz="0.0" iyy="0.00001" iyz="0.0" izz="0.0000018"/>
    </inertial>
    <visual>
      <origin rpy="0 0 0" xyz="0 0 0"/>
      <geometry name="rfproximal_visual">
        <mesh filename="package://sr_description/meshes/components/f_proximal/f_proximal_E3M5.dae" scale="0.001 0.001 0.001"/>
      </geometry>
      <material name="Grey"/>
    </visual>
    <collision>
      <origin rpy="0 0 0" xyz="0 0 0.025"/>
      <geometry name="rfproximal_collision_geom">
        <cylinder length="0.040" radius="0.007"/>
      </geometry>
    </collision>
  </link>
  <joint name="RFJ3" type="revolute">
    <parent link="rfknuckle"/>
    <child link="rfproximal"/>
    <origin rpy="0 0 0" xyz="0 0 0"/>
    <axis xyz="1 0 0"/>
    <limit effort="2" lower="-0.2617993877991494" upper="1.5707963267948966" velocity="2.0"/>
    <dynamics damping="0.1"/>
  </joint>
 
  <link name="rfmiddle">
    <inertial>
      <origin rpy="0 0 0" xyz="0 0 0.0125"/>
      <mass value="0.017"/>
      <inertia ixx="0.0000026" ixy="0.0" ixz="0.0" iyy="0.0000027" iyz="0.0" izz="0.00000087"/>
    </inertial>
    <visual>
      <origin rpy="0 0 0" xyz="0 0 0"/>
      <geometry name="rfmiddle_visual">
        <mesh filename="package://sr_description/meshes/components/f_middle/f_middle_E3M5.dae" scale="0.001 0.001 0.001"/>
      </geometry>
      <material name="Grey"/>
    </visual>
    <collision>
      <origin rpy="0 0 0" xyz="0 0 0.0125"/>
      <geometry name="rfmiddle_collision_geom">
        <cylinder length="0.025" radius="0.007"/>
      </geometry>
    </collision>
    <collision>
      <origin rpy="0 0 0" xyz="0 0 0.0"/>
      <geometry>
        <sphere radius="0.007"/>
      </geometry>
    </collision>
    <collision>
      <origin rpy="0 0 0" xyz="0 0 0.025"/>
      <geometry>
        <sphere radius="0.007"/>
      </geometry>
    </collision>
  </link>
  <joint name="RFJ2" type="revolute">
    <parent link="rfproximal"/>
    <child link="rfmiddle"/>
    <origin rpy="0 0 0" xyz="0 0 0.045"/>
    <axis xyz="1 0 0"/>
    <limit effort="2" lower="0" upper="1.5707963267948966" velocity="2.0"/>
    <dynamics damping="0.1"/>
  </joint>

  <link name="rfdistal">
    <inertial>
      <mass value="0.012"/>
      <origin xyz="0 0 0.012"/>
      <inertia ixx="0.00000094" ixy="0.0" ixz="0.0" iyy="0.0000011" iyz="0.0" izz="0.00000053"/>
    </inertial>
    <visual>
      <origin rpy="0 0 0" xyz="0 0 0"/>
      <geometry name="rfdistal_visual">
        <mesh filename="package://sr_description/meshes/components/f_distal/pst/f_distal_pst.dae" scale="0.001 0.001 0.001"/>
      </geometry>
    </visual>
    <collision>
      <origin rpy="0 0 0" xyz="0 0 0"/>
      <geometry name="rfdistal_collision_geom">
        <mesh filename="package://sr_description/meshes/components/f_distal/pst/f_distal_pst.dae" scale="0.001 0.001 0.001"/>
      </geometry>
    </collision>
  </link>
  <joint name="RFJ1" type="revolute">
    <parent link="rfmiddle"/>
    <child link="rfdistal"/>
    <origin rpy="0 0 0" xyz="0 0 0.025"/>
    <axis xyz="1 0 0"/>
    <!-- standard distal joint -->
    <limit effort="2" lower="0" upper="1.5707963267948966" velocity="2.0"/>
    <dynamics damping="0.1"/>
  </joint>
  
  <link name="rftip">
    <inertial>
      <mass value="0.001"/>
      <inertia ixx="0.0" ixy="0.0" ixz="0.0" iyy="0.0" iyz="0.0" izz="0.0"/>
    </inertial>
  </link>
  <joint name="RFtip" type="fixed">
    <parent link="rfdistal"/>
    <child link="rftip"/>
    <origin rpy="0 0 0" xyz="0 0 0.026"/>
  </joint>

  <link name="lfmetacarpal">
    <inertial>
      <origin rpy="0 0 0" xyz="0 0 0.04"/>
      <mass value="0.030"/>
      <inertia ixx="0.0000145" ixy="0.0" ixz="0.0" iyy="0.00001638" iyz="0.0" izz="0.000004272"/>
    </inertial>
    <visual>
      <origin rpy="0 0.9599 0" xyz="0 0 0"/>
      <geometry name="lfmetacarpal_visual">
        <mesh filename="package://sr_description/meshes/components/lf_metacarpal/lf_metacarpal_E3M5.dae" scale="0.001 0.001 0.001"/>
      </geometry>
      <material name="Grey"/>
    </visual>
    <collision>
      <origin rpy="0 0.9599 0" xyz="0.026986375 0 0.019"/>
      <geometry name="lfmetacarpal_collision_geom">
        <box size="0.018 0.024 0.040"/>
      </geometry>
    </collision>
  </link>
  <joint name="LFJ5" type="revolute">
    <parent link="palm"/>
    <child link="lfmetacarpal"/>
    <origin rpy="0 -0.9599 0" xyz="-0.033 0 0.02071"/>
    <axis xyz="1 0 0"/>
    <limit effort="2" lower="0" upper="0.7853981633974483" velocity="2.0"/>
    <dynamics damping="0.1"/>
  </joint>
 
  <link name="lfknuckle">
    <inertial>
      <origin rpy="0 0 0" xyz="0 0 0"/>
      <mass value="0.008"/>
      <inertia ixx="0.00000026" ixy="0.0" ixz="0.0" iyy="0.00000026" iyz="0.0" izz="0.00000032"/>
    </inertial>
    <visual>
      <origin rpy="0 0 0" xyz="0 0 0.0005"/>
      <geometry name="lfknuckle_visual">
        <mesh filename="package://sr_description/meshes/components/f_knuckle/f_knuckle_E3M5.dae" scale="0.001 0.001 0.001"/>
      </geometry>
      <material name="LightGrey"/>
    </visual>
    <collision>
      <origin rpy="0 1.5708 0" xyz="0 0 0"/>
      <geometry name="lfknuckle_collision_geom">
        <cylinder length="0.014" radius="0.007"/>
      </geometry>
    </collision>
  </link>
  <joint name="LFJ4" type="revolute">
    <parent link="lfmetacarpal"/>
    <child link="lfknuckle"/>
    <!--<origin xyz="0.033 0 0.095" rpy="0 0 0" />-->
    <origin rpy="0 0.9599 0" xyz="0.05397275 0 0.03779463"/>
    <axis xyz="0 1 0"/>
    <limit effort="2" lower="-0.3490658503988659" upper="0.3490658503988659" velocity="2.0"/>
    <dynamics damping="0.1"/>
  </joint>
 
  <link name="lfproximal">
    <inertial>
      <mass value="0.030"/>
      <origin xyz="0 0 0.0225"/>
      <inertia ixx="0.0000098" ixy="0.0" ixz="0.0" iyy="0.00001" iyz="0.0" izz="0.0000018"/>
    </inertial>
    <visual>
      <origin rpy="0 0 0" xyz="0 0 0"/>
      <geometry name="lfproximal_visual">
        <mesh filename="package://sr_description/meshes/components/f_proximal/f_proximal_E3M5.dae" scale="0.001 0.001 0.001"/>
      </geometry>
      <material name="Grey"/>
    </visual>
    <collision>
      <origin rpy="0 0 0" xyz="0 0 0.025"/>
      <geometry name="lfproximal_collision_geom">
        <cylinder length="0.040" radius="0.007"/>
      </geometry>
    </collision>
  </link>
  <joint name="LFJ3" type="revolute">
    <parent link="lfknuckle"/>
    <child link="lfproximal"/>
    <origin rpy="0 0 0" xyz="0 0 0"/>
    <axis xyz="1 0 0"/>
    <limit effort="2" lower="-0.2617993877991494" upper="1.5707963267948966" velocity="2.0"/>
    <dynamics damping="0.1"/>
  </joint>
  
  <link name="lfmiddle">
    <inertial>
      <origin rpy="0 0 0" xyz="0 0 0.0125"/>
      <mass value="0.017"/>
      <inertia ixx="0.0000026" ixy="0.0" ixz="0.0" iyy="0.0000027" iyz="0.0" izz="0.00000087"/>
    </inertial>
    <visual>
      <origin rpy="0 0 0" xyz="0 0 0"/>
      <geometry name="lfmiddle_visual">
        <mesh filename="package://sr_description/meshes/components/f_middle/f_middle_E3M5.dae" scale="0.001 0.001 0.001"/>
      </geometry>
      <material name="Grey"/>
    </visual>
    <collision>
      <origin rpy="0 0 0" xyz="0 0 0.0125"/>
      <geometry name="lfmiddle_collision_geom">
        <cylinder length="0.025" radius="0.007"/>
      </geometry>
    </collision>
    <collision>
      <origin rpy="0 0 0" xyz="0 0 0.0"/>
      <geometry>
        <sphere radius="0.007"/>
      </geometry>
    </collision>
    <collision>
      <origin rpy="0 0 0" xyz="0 0 0.025"/>
      <geometry>
        <sphere radius="0.007"/>
      </geometry>
    </collision>
  </link>
  <joint name="LFJ2" type="revolute">
    <parent link="lfproximal"/>
    <child link="lfmiddle"/>
    <origin rpy="0 0 0" xyz="0 0 0.045"/>
    <axis xyz="1 0 0"/>
    <limit effort="2" lower="0" upper="1.5707963267948966" velocity="2.0"/>
    <dynamics damping="0.1"/>
  </joint>
  

  <link name="lfdistal">
    <inertial>
      <mass value="0.012"/>
      <origin xyz="0 0 0.012"/>
      <inertia ixx="0.00000094" ixy="0.0" ixz="0.0" iyy="0.0000011" iyz="0.0" izz="0.00000053"/>
    </inertial>
    <visual>
      <origin rpy="0 0 0" xyz="0 0 0"/>
      <geometry name="lfdistal_visual">
        <mesh filename="package://sr_description/meshes/components/f_distal/pst/f_distal_pst.dae" scale="0.001 0.001 0.001"/>
      </geometry>
    </visual>
    <collision>
      <origin rpy="0 0 0" xyz="0 0 0"/>
      <geometry name="lfdistal_collision_geom">
        <mesh filename="package://sr_description/meshes/components/f_distal/pst/f_distal_pst.dae" scale="0.001 0.001 0.001"/>
      </geometry>
    </collision>
  </link>
  <joint name="LFJ1" type="revolute">
    <parent link="lfmiddle"/>
    <child link="lfdistal"/>
    <origin rpy="0 0 0" xyz="0 0 0.025"/>
    <axis xyz="1 0 0"/>
    <!-- standard distal joint -->
    <limit effort="2" lower="0" upper="1.5707963267948966" velocity="2.0"/>
    <dynamics damping="0.1"/>
  </joint>
  
  <link name="lftip">
    <inertial>
      <mass value="0.001"/>
      <inertia ixx="0.0" ixy="0.0" ixz="0.0" iyy="0.0" iyz="0.0" izz="0.0"/>
    </inertial>
  </link>
  
  <joint name="LFtip" type="fixed">
    <parent link="lfdistal"/>
    <child link="lftip"/>
    <origin rpy="0 0 0" xyz="0 0 0.026"/>
  </joint>
  <link name="thbase">
    <inertial>
      <mass value="0.010"/>
      <origin rpy="0 0 0" xyz="0 0 0"/>
      <inertia ixx="0.00000016" ixy="0.0" ixz="0.0" iyy="0.00000016" iyz="0.0" izz="0.00000016"/>
    </inertial>
    <visual>
      <origin rpy="0 0 0" xyz="0 0 0"/>
      <geometry name="thbase_visual">
        <box size="0.001 0.001 0.001"/>
      </geometry>
      <material name="shadow_thbase_material">
        <color rgba="0.5 0.5 0.5 1.0"/>
      </material>
    </visual>
    <collision>
      <origin rpy="0 0 0" xyz="0 0 0"/>
      <geometry name="thbase_collision_geom">
        <sphere radius="0.011"/>
      </geometry>
    </collision>
  </link>
  <joint name="THJ5" type="revolute">
    <parent link="palm"/>
    <child link="thbase"/>
    <origin rpy="-0.7853981633974483 0 -1.5707963267948966" xyz="0.034 -0.00858 0.029"/>
    <axis xyz="0 0 -1"/>
    <limit effort="5.0" lower="-1.0471975511965976" upper="1.0471975511965976" velocity="4.0"/>
    <dynamics damping="0.2"/>
  </joint>
 
  <link name="thproximal">
    <inertial>
      <mass value="0.040"/>
      <origin rpy="0 0 0" xyz="0 0 0.019"/>
      <inertia ixx="0.0000136" ixy="0.0" ixz="0.0" iyy="0.0000136" iyz="0.0" izz="0.00000313"/>
    </inertial>
    <visual>
      <origin rpy="0 0 0" xyz="0 0 0"/>
      <geometry name="thproximal_visual">
        <mesh filename="package://sr_description/meshes/components/th_proximal/th_proximal_E3M5.dae" scale="0.001 0.001 0.001"/>
      </geometry>
      <material name="shadow_thproximal_material">
        <color rgba="0.2 0.2 0.2 1.0"/>
      </material>
    </visual>
    <collision>
      <origin rpy="0 0 0" xyz="0 0 0.020"/>
      <geometry name="thproximal_collision_geom">
        <cylinder length="0.018" radius="0.012"/>
      </geometry>
    </collision>
  </link>
  <joint name="THJ4" type="revolute">
    <parent link="thbase"/>
    <child link="thproximal"/>
    <origin rpy="0 0 0" xyz="0 0 0"/>
    <axis xyz="0 1 0"/>
    <limit effort="3" lower="0.0" upper="1.2217304763960306" velocity="4.0"/>
    <dynamics damping="0.2"/>
  </joint>
 
  <link name="thhub">
    <inertial>
      <mass value="0.005"/>
      <origin rpy="0 0 0" xyz="0 0 0"/>
      <inertia ixx="0.000001" ixy="0.0" ixz="0.0" iyy="0.000001" iyz="0.0" izz="0.0000003"/>
    </inertial>
    <visual>
      <origin rpy="0 0 0" xyz="0 0 0"/>
      <geometry name="thhub_visual">
        <box size="0.001 0.001 0.001"/>
      </geometry>
      <material name="shadow_thhub_material">
        <color rgba="0.7 0.7 0.7 1.0"/>
      </material>
    </visual>
    <collision>
      <origin rpy="0 0 0" xyz="0 0 0"/>
      <geometry name="thhub_collision_geom">
        <sphere radius="0.010"/>
      </geometry>
    </collision>
  </link>
  <joint name="THJ3" type="revolute">
    <parent link="thproximal"/>
    <child link="thhub"/>
    <origin rpy="0 0 0" xyz="0 0 0.038"/>
    <axis xyz="0 1 0"/>
    <limit effort="2.0" lower="-0.20943951023931953" upper="0.20943951023931953" velocity="4.0"/>
    <dynamics damping="0.2"/>
  </joint>
  
 
  <link name="thmiddle">
    <inertial>
      <mass value="0.020"/>
      <origin rpy="0 0 0" xyz="0 0 0.016"/>
      <inertia ixx="0.0000051" ixy="0.0" ixz="0.0" iyy="0.0000051" iyz="0.0" izz="0.00000121"/>
    </inertial>
    <visual>
      <origin rpy="0 0 0" xyz="0 0 0"/>
      <geometry name="thmiddle_visual">
        <mesh filename="package://sr_description/meshes/components/th_middle/th_middle_E3M5.dae" scale="0.001 0.001 0.001"/>
      </geometry>
      <material name="shadow_thmiddle_material">
        <color rgba="0.2 0.2 0.2 1.0"/>
      </material>
    </visual>
    <collision>
      <origin rpy="0 0 0" xyz="0 0 0.012"/>
      <geometry name="thmiddle_collision_geom">
        <cylinder length="0.018" radius="0.011"/>
      </geometry>
    </collision>
    <collision>
      <origin rpy="0 0 0" xyz="0 0 0.019"/>
      <geometry>
        <sphere radius="0.011"/>
      </geometry>
    </collision>
    <collision>
      <origin rpy="0 1.5708 0" xyz="0 0 0.032"/>
      <geometry>
        <cylinder length="0.014" radius="0.010"/>
      </geometry>
    </collision>
  </link>
  <joint name="THJ2" type="revolute">
    <parent link="thhub"/>
    <child link="thmiddle"/>
    <origin rpy="0 0 0" xyz="0 0 0"/>
    <axis xyz="1 0 0"/>
    <limit effort="2.0" lower="-0.6981317007977318" upper="0.6981317007977318" velocity="2.0"/>
    <dynamics damping="0.1"/>
  </joint>
  
  <!-- common -->
  <link name="thdistal">
    <inertial>
      <mass value="0.016"/>
      <origin rpy="0 0 0" xyz="0 0 0.01375"/>
      <inertia ixx="0.0000021" ixy="0.0" ixz="0.0" iyy="0.0000022" iyz="0.0" izz="0.000001"/>
    </inertial>
    <visual>
      <origin rpy="0 0 0" xyz="0 0 0"/>
      <geometry name="thdistal_visual">
        <mesh filename="package://sr_description/meshes/components/th_distal/pst/th_distal_pst.dae" scale="0.001 0.001 0.001"/>
      </geometry>
      <material name="shadow_thmiddle_material">
        <color rgba="0.2 0.2 0.2 1.0"/>
      </material>
    </visual>
    <collision>
      <origin rpy="0 0 0" xyz="0 0 0"/>
      <geometry name="thmiddle_collision_geom">
        <mesh filename="package://sr_description/meshes/components/th_distal/pst/th_distal_pst.dae" scale="0.001 0.001 0.001"/>
      </geometry>
    </collision>
  </link>
  <joint name="THJ1" type="revolute">
    <parent link="thmiddle"/>
    <child link="thdistal"/>
    <origin rpy="0 0 0" xyz="0 0 0.032"/>
    <axis xyz="1 0 0"/>
    <limit effort="1.0" lower="-0.2617993877991494" upper="1.5707963267948966" velocity="4.0"/>
    <dynamics damping="0.2"/>
  </joint>
  
  <link name="thtip">
    <inertial>
      <mass value="0.001"/>
      <inertia ixx="0.0" ixy="0.0" ixz="0.0" iyy="0.0" iyz="0.0" izz="0.0"/>
    </inertial>
  </link>
  <joint name="thtip" type="fixed">
    <parent link="thdistal"/>
    <child link="thtip"/>
    <origin rpy="0 0 0" xyz="0 0 0.0275"/>
  </joint>
 
  <joint name="world_joint" type="fixed">
    <parent link="world"/>
    <child link="base_link"/>
    <origin rpy="0.0 0.0 0.0" xyz="0.0 0.0 0.0"/>
  </joint>
  <joint name="arm_to_hand" type="fixed">
    <parent link="flange"/>
    <child link="forearm"/>
    <origin rpy="1.5707963267948966 3.141592653589793 1.5707963267948966" xyz="0.0 0.0 0.0"/>
  </joint>
</robot>

