<?xml version='1.0' encoding='ASCII'?>
<robot name="A02L_MP">
  <link name="world"/>
  <link name="base_link">
    <inertial>
      <origin xyz="0.0 0.0 0.09" rpy="0.0 -0.0 0.0"/>
      <mass value="3.7"/>
      <inertia ixx="0.019" ixy="0.0" ixz="0.0" iyy="0.02" iyz="0.0" izz="0.009"/>
    </inertial>
    <visual>
      <geometry>
        <mesh filename="/home/xuehan/Projects/curobo/src/curobo/content/assets/robot/flexiv_description/meshes/visual/link0.stl"/>
      </geometry>
      <origin xyz="0.0 0.0 0.0" rpy="0.0 -0.0 0.0"/>
      <material name="rizon_light_grey"/>
    </visual>
    <collision>
      <geometry>
        <mesh filename="/home/xuehan/Projects/curobo/src/curobo/content/assets/robot/flexiv_description/meshes/collision/link0.stl"/>
      </geometry>
      <origin xyz="0.0 0.0 0.0" rpy="0.0 -0.0 0.0"/>
    </collision>
  </link>
  <link name="link1">
    <inertial>
      <origin xyz="0.0 0.01 0.15" rpy="0.0 -0.0 0.0"/>
      <mass value="3.7"/>
      <inertia ixx="0.028" ixy="0.0" ixz="0.0" iyy="0.027" iyz="0.002" izz="0.008"/>
    </inertial>
    <visual>
      <geometry>
        <mesh filename="/home/xuehan/Projects/curobo/src/curobo/content/assets/robot/flexiv_description/meshes/visual/link1.stl"/>
      </geometry>
      <origin xyz="0.0 0.0 0.0" rpy="0.0 -0.0 0.0"/>
      <material name="rizon_light_grey"/>
    </visual>
    <collision>
      <geometry>
        <mesh filename="/home/xuehan/Projects/curobo/src/curobo/content/assets/robot/flexiv_description/meshes/collision/link1.stl"/>
      </geometry>
      <origin xyz="0.0 0.0 0.0" rpy="0.0 -0.0 0.0"/>
    </collision>
  </link>
  <link name="link2">
    <inertial>
      <origin xyz="0.0 0.04 0.1" rpy="0.0 -0.0 0.0"/>
      <mass value="2.7"/>
      <inertia ixx="0.023" ixy="0.0" ixz="0.0" iyy="0.024" iyz="-0.0" izz="0.004"/>
    </inertial>
    <visual>
      <geometry>
        <mesh filename="/home/xuehan/Projects/curobo/src/curobo/content/assets/robot/flexiv_description/meshes/visual/link2.stl"/>
      </geometry>
      <origin xyz="0.0 0.0 0.0" rpy="0.0 -0.0 0.0"/>
      <material name="rizon_light_grey"/>
    </visual>
    <collision>
      <geometry>
        <mesh filename="/home/xuehan/Projects/curobo/src/curobo/content/assets/robot/flexiv_description/meshes/collision/link2.stl"/>
      </geometry>
      <origin xyz="0.0 0.0 0.0" rpy="0.0 -0.0 0.0"/>
    </collision>
  </link>
  <link name="link3">
    <inertial>
      <origin xyz="-0.01 0.0 0.13" rpy="0.0 -0.0 0.0"/>
      <mass value="2.4"/>
      <inertia ixx="0.014" ixy="0.0" ixz="-0.001" iyy="0.014" iyz="-0.001" izz="0.004"/>
    </inertial>
    <visual>
      <geometry>
        <mesh filename="/home/xuehan/Projects/curobo/src/curobo/content/assets/robot/flexiv_description/meshes/visual/link3.stl"/>
      </geometry>
      <origin xyz="0.0 0.0 0.0" rpy="0.0 -0.0 0.0"/>
      <material name="rizon_light_grey"/>
    </visual>
    <collision>
      <geometry>
        <mesh filename="/home/xuehan/Projects/curobo/src/curobo/content/assets/robot/flexiv_description/meshes/collision/link3.stl"/>
      </geometry>
      <origin xyz="0.0 0.0 0.0" rpy="0.0 -0.0 0.0"/>
    </collision>
  </link>
  <link name="link4">
    <inertial>
      <origin xyz="-0.01 0.03 0.1" rpy="0.0 -0.0 0.0"/>
      <mass value="2.4"/>
      <inertia ixx="0.018" ixy="0.0" ixz="-0.002" iyy="0.019" iyz="-0.001" izz="0.003"/>
    </inertial>
    <visual>
      <geometry>
        <mesh filename="/home/xuehan/Projects/curobo/src/curobo/content/assets/robot/flexiv_description/meshes/visual/link4.stl"/>
      </geometry>
      <origin xyz="0.0 0.0 0.0" rpy="0.0 -0.0 0.0"/>
      <material name="rizon_light_grey"/>
    </visual>
    <collision>
      <geometry>
        <mesh filename="/home/xuehan/Projects/curobo/src/curobo/content/assets/robot/flexiv_description/meshes/collision/link4.stl"/>
      </geometry>
      <origin xyz="0.0 0.0 0.0" rpy="0.0 -0.0 0.0"/>
    </collision>
  </link>
  <link name="link5">
    <inertial>
      <origin xyz="0.0 0.0 0.13" rpy="0.0 -0.0 0.0"/>
      <mass value="2.4"/>
      <inertia ixx="0.014" ixy="0.0" ixz="0.0" iyy="0.013" iyz="0.001" izz="0.004"/>
    </inertial>
    <visual>
      <geometry>
        <mesh filename="/home/xuehan/Projects/curobo/src/curobo/content/assets/robot/flexiv_description/meshes/visual/link5.stl"/>
      </geometry>
      <origin xyz="0.0 0.0 0.0" rpy="0.0 -0.0 0.0"/>
      <material name="rizon_light_grey"/>
    </visual>
    <collision>
      <geometry>
        <mesh filename="/home/xuehan/Projects/curobo/src/curobo/content/assets/robot/flexiv_description/meshes/collision/link5.stl"/>
      </geometry>
      <origin xyz="0.0 0.0 0.0" rpy="0.0 -0.0 0.0"/>
    </collision>
  </link>
  <link name="link6">
    <inertial>
      <origin xyz="-0.01 0.06 0.07" rpy="0.0 -0.0 0.0"/>
      <mass value="2.1"/>
      <inertia ixx="0.008" ixy="-0.0" ixz="-0.001" iyy="0.009" iyz="0.002" izz="0.004"/>
    </inertial>
    <visual>
      <geometry>
        <mesh filename="/home/xuehan/Projects/curobo/src/curobo/content/assets/robot/flexiv_description/meshes/visual/link6.stl"/>
      </geometry>
      <origin xyz="0.0 0.0 0.0" rpy="0.0 -0.0 0.0"/>
      <material name="rizon_light_grey"/>
    </visual>
    <collision>
      <geometry>
        <mesh filename="/home/xuehan/Projects/curobo/src/curobo/content/assets/robot/flexiv_description/meshes/collision/link6.stl"/>
      </geometry>
      <origin xyz="0.0 0.0 0.0" rpy="0.0 -0.0 0.0"/>
    </collision>
  </link>
  <link name="link7">
    <inertial>
      <origin xyz="0.0 0.0 0.03" rpy="0.0 -0.0 0.0"/>
      <mass value="0.8"/>
      <inertia ixx="0.001" ixy="0.0" ixz="0.0" iyy="0.001" iyz="0.0" izz="0.001"/>
    </inertial>
    <visual>
      <geometry>
        <mesh filename="/home/xuehan/Projects/curobo/src/curobo/content/assets/robot/flexiv_description/meshes/visual/link7.stl"/>
      </geometry>
      <origin xyz="0.0 0.0 0.0" rpy="0.0 -0.0 0.0"/>
      <material name="rizon_light_grey"/>
    </visual>
    <collision>
      <geometry>
        <mesh filename="/home/xuehan/Projects/curobo/src/curobo/content/assets/robot/flexiv_description/meshes/collision/link7.stl"/>
      </geometry>
      <origin xyz="0.0 0.0 0.0" rpy="0.0 -0.0 0.0"/>
    </collision>
  </link>
  <link name="flange"/>
  <link name="base_link_1">
    <inertial>
      <origin xyz="0.0 0.0 0.09" rpy="0.0 -0.0 0.0"/>
      <mass value="3.7"/>
      <inertia ixx="0.019" ixy="0.0" ixz="0.0" iyy="0.02" iyz="0.0" izz="0.009"/>
    </inertial>
    <visual>
      <geometry>
        <mesh filename="/home/xuehan/Projects/curobo/src/curobo/content/assets/robot/flexiv_description/meshes/visual/link0.stl"/>
      </geometry>
      <origin xyz="0.0 0.0 0.0" rpy="0.0 -0.0 0.0"/>
      <material name="rizon_light_grey"/>
    </visual>
    <collision>
      <geometry>
        <mesh filename="/home/xuehan/Projects/curobo/src/curobo/content/assets/robot/flexiv_description/meshes/collision/link0.stl"/>
      </geometry>
      <origin xyz="0.0 0.0 0.0" rpy="0.0 -0.0 0.0"/>
    </collision>
  </link>
  <link name="link1_1">
    <inertial>
      <origin xyz="0.0 0.01 0.15" rpy="0.0 -0.0 0.0"/>
      <mass value="3.7"/>
      <inertia ixx="0.028" ixy="0.0" ixz="0.0" iyy="0.027" iyz="0.002" izz="0.008"/>
    </inertial>
    <visual>
      <geometry>
        <mesh filename="/home/xuehan/Projects/curobo/src/curobo/content/assets/robot/flexiv_description/meshes/visual/link1.stl"/>
      </geometry>
      <origin xyz="0.0 0.0 0.0" rpy="0.0 -0.0 0.0"/>
      <material name="rizon_light_grey"/>
    </visual>
    <collision>
      <geometry>
        <mesh filename="/home/xuehan/Projects/curobo/src/curobo/content/assets/robot/flexiv_description/meshes/collision/link1.stl"/>
      </geometry>
      <origin xyz="0.0 0.0 0.0" rpy="0.0 -0.0 0.0"/>
    </collision>
  </link>
  <link name="link2_1">
    <inertial>
      <origin xyz="0.0 0.04 0.1" rpy="0.0 -0.0 0.0"/>
      <mass value="2.7"/>
      <inertia ixx="0.023" ixy="0.0" ixz="0.0" iyy="0.024" iyz="-0.0" izz="0.004"/>
    </inertial>
    <visual>
      <geometry>
        <mesh filename="/home/xuehan/Projects/curobo/src/curobo/content/assets/robot/flexiv_description/meshes/visual/link2.stl"/>
      </geometry>
      <origin xyz="0.0 0.0 0.0" rpy="0.0 -0.0 0.0"/>
      <material name="rizon_light_grey"/>
    </visual>
    <collision>
      <geometry>
        <mesh filename="/home/xuehan/Projects/curobo/src/curobo/content/assets/robot/flexiv_description/meshes/collision/link2.stl"/>
      </geometry>
      <origin xyz="0.0 0.0 0.0" rpy="0.0 -0.0 0.0"/>
    </collision>
  </link>
  <link name="link3_1">
    <inertial>
      <origin xyz="-0.01 0.0 0.13" rpy="0.0 -0.0 0.0"/>
      <mass value="2.4"/>
      <inertia ixx="0.014" ixy="0.0" ixz="-0.001" iyy="0.014" iyz="-0.001" izz="0.004"/>
    </inertial>
    <visual>
      <geometry>
        <mesh filename="/home/xuehan/Projects/curobo/src/curobo/content/assets/robot/flexiv_description/meshes/visual/link3.stl"/>
      </geometry>
      <origin xyz="0.0 0.0 0.0" rpy="0.0 -0.0 0.0"/>
      <material name="rizon_light_grey"/>
    </visual>
    <collision>
      <geometry>
        <mesh filename="/home/xuehan/Projects/curobo/src/curobo/content/assets/robot/flexiv_description/meshes/collision/link3.stl"/>
      </geometry>
      <origin xyz="0.0 0.0 0.0" rpy="0.0 -0.0 0.0"/>
    </collision>
  </link>
  <link name="link4_1">
    <inertial>
      <origin xyz="-0.01 0.03 0.1" rpy="0.0 -0.0 0.0"/>
      <mass value="2.4"/>
      <inertia ixx="0.018" ixy="0.0" ixz="-0.002" iyy="0.019" iyz="-0.001" izz="0.003"/>
    </inertial>
    <visual>
      <geometry>
        <mesh filename="/home/xuehan/Projects/curobo/src/curobo/content/assets/robot/flexiv_description/meshes/visual/link4.stl"/>
      </geometry>
      <origin xyz="0.0 0.0 0.0" rpy="0.0 -0.0 0.0"/>
      <material name="rizon_light_grey"/>
    </visual>
    <collision>
      <geometry>
        <mesh filename="/home/xuehan/Projects/curobo/src/curobo/content/assets/robot/flexiv_description/meshes/collision/link4.stl"/>
      </geometry>
      <origin xyz="0.0 0.0 0.0" rpy="0.0 -0.0 0.0"/>
    </collision>
  </link>
  <link name="link5_1">
    <inertial>
      <origin xyz="0.0 0.0 0.13" rpy="0.0 -0.0 0.0"/>
      <mass value="2.4"/>
      <inertia ixx="0.014" ixy="0.0" ixz="0.0" iyy="0.013" iyz="0.001" izz="0.004"/>
    </inertial>
    <visual>
      <geometry>
        <mesh filename="/home/xuehan/Projects/curobo/src/curobo/content/assets/robot/flexiv_description/meshes/visual/link5.stl"/>
      </geometry>
      <origin xyz="0.0 0.0 0.0" rpy="0.0 -0.0 0.0"/>
      <material name="rizon_light_grey"/>
    </visual>
    <collision>
      <geometry>
        <mesh filename="/home/xuehan/Projects/curobo/src/curobo/content/assets/robot/flexiv_description/meshes/collision/link5.stl"/>
      </geometry>
      <origin xyz="0.0 0.0 0.0" rpy="0.0 -0.0 0.0"/>
    </collision>
  </link>
  <link name="link6_1">
    <inertial>
      <origin xyz="-0.01 0.06 0.07" rpy="0.0 -0.0 0.0"/>
      <mass value="2.1"/>
      <inertia ixx="0.008" ixy="-0.0" ixz="-0.001" iyy="0.009" iyz="0.002" izz="0.004"/>
    </inertial>
    <visual>
      <geometry>
        <mesh filename="/home/xuehan/Projects/curobo/src/curobo/content/assets/robot/flexiv_description/meshes/visual/link6.stl"/>
      </geometry>
      <origin xyz="0.0 0.0 0.0" rpy="0.0 -0.0 0.0"/>
      <material name="rizon_light_grey"/>
    </visual>
    <collision>
      <geometry>
        <mesh filename="/home/xuehan/Projects/curobo/src/curobo/content/assets/robot/flexiv_description/meshes/collision/link6.stl"/>
      </geometry>
      <origin xyz="0.0 0.0 0.0" rpy="0.0 -0.0 0.0"/>
    </collision>
  </link>
  <link name="link7_1">
    <inertial>
      <origin xyz="0.0 0.0 0.03" rpy="0.0 -0.0 0.0"/>
      <mass value="0.8"/>
      <inertia ixx="0.001" ixy="0.0" ixz="0.0" iyy="0.001" iyz="0.0" izz="0.001"/>
    </inertial>
    <visual>
      <geometry>
        <mesh filename="/home/xuehan/Projects/curobo/src/curobo/content/assets/robot/flexiv_description/meshes/visual/link7.stl"/>
      </geometry>
      <origin xyz="0.0 0.0 0.0" rpy="0.0 -0.0 0.0"/>
      <material name="rizon_light_grey"/>
    </visual>
    <collision>
      <geometry>
        <mesh filename="/home/xuehan/Projects/curobo/src/curobo/content/assets/robot/flexiv_description/meshes/collision/link7.stl"/>
      </geometry>
      <origin xyz="0.0 0.0 0.0" rpy="0.0 -0.0 0.0"/>
    </collision>
  </link>
  <link name="flange_1"/>
  <link name="ee_target"/>
  <link name="ee_target_1"/>
  <joint name="joint0" type="fixed">
    <parent link="world"/>
    <child link="base_link"/>
    <origin xyz="0.0 0.313 0.0" rpy="0.0 -0.0 0.0"/>
    <axis xyz="1.0 0.0 0.0"/>
  </joint>
  <joint name="joint0_1" type="fixed">
    <parent link="world"/>
    <child link="base_link_1"/>
    <origin xyz="0.0 -0.313 0.0" rpy="0.0 -0.0 0.0"/>
    <axis xyz="1.0 0.0 0.0"/>
  </joint>
  <joint name="joint1" type="revolute">
    <parent link="base_link"/>
    <child link="link1"/>
    <origin xyz="0.0 0.0 0.155" rpy="0.0 -0.0 3.141592653589793"/>
    <axis xyz="0.0 0.0 1.0"/>
    <limit effort="123.0" velocity="2.0944" lower="-2.58" upper="2.58"/>
  </joint>
  <joint name="joint2" type="revolute">
    <parent link="link1"/>
    <child link="link2"/>
    <origin xyz="0.0 0.03 0.21" rpy="0.0 -0.0 0.0"/>
    <axis xyz="0.0 1.0 0.0"/>
    <limit effort="123.0" velocity="2.0944" lower="-2.05" upper="2.05"/>
  </joint>
  <joint name="joint3" type="revolute">
    <parent link="link2"/>
    <child link="link3"/>
    <origin xyz="0.0 0.035 0.205" rpy="0.0 -0.0 0.0"/>
    <axis xyz="0.0 0.0 1.0"/>
    <limit effort="64.0" velocity="2.4435" lower="-2.75" upper="2.75"/>
  </joint>
  <joint name="joint4" type="revolute">
    <parent link="link3"/>
    <child link="link4"/>
    <origin xyz="-0.02 -0.03 0.19" rpy="0.0 -0.0 -3.141592653589793"/>
    <axis xyz="0.0 1.0 0.0"/>
    <limit effort="64.0" velocity="2.4435" lower="-1.64" upper="2.47"/>
  </joint>
  <joint name="joint5" type="revolute">
    <parent link="link4"/>
    <child link="link5"/>
    <origin xyz="-0.02 0.025 0.195" rpy="0.0 -0.0 -3.141592653589793"/>
    <axis xyz="0.0 0.0 1.0"/>
    <limit effort="39.0" velocity="4.8869" lower="-2.77" upper="2.77"/>
  </joint>
  <joint name="joint6" type="revolute">
    <parent link="link5"/>
    <child link="link6"/>
    <origin xyz="0.0 0.03 0.19" rpy="0.0 -0.0 0.0"/>
    <axis xyz="0.0 1.0 0.0"/>
    <limit effort="39.0" velocity="4.8869" lower="-1.21" upper="4.35"/>
  </joint>
  <joint name="joint7" type="revolute">
    <parent link="link6"/>
    <child link="link7"/>
    <origin xyz="-0.055 0.07 0.11" rpy="-0.0 -1.5707963267948966 0.0"/>
    <axis xyz="0.0 0.0 1.0"/>
    <limit effort="39.0" velocity="4.8869" lower="-2.77" upper="2.77"/>
  </joint>
  <joint name="link7_to_flange" type="fixed">
    <parent link="link7"/>
    <child link="flange"/>
    <origin xyz="0.0 0.0 0.081" rpy="0.0 -0.0 -3.141592653589793"/>
    <axis xyz="1.0 0.0 0.0"/>
  </joint>
  <joint name="joint1_1" type="revolute">
    <parent link="base_link_1"/>
    <child link="link1_1"/>
    <origin xyz="0.0 0.0 0.155" rpy="0.0 -0.0 3.141592653589793"/>
    <axis xyz="0.0 0.0 1.0"/>
    <limit effort="123.0" velocity="2.0944" lower="-2.58" upper="2.58"/>
  </joint>
  <joint name="joint2_1" type="revolute">
    <parent link="link1_1"/>
    <child link="link2_1"/>
    <origin xyz="0.0 0.03 0.21" rpy="0.0 -0.0 0.0"/>
    <axis xyz="0.0 1.0 0.0"/>
    <limit effort="123.0" velocity="2.0944" lower="-2.05" upper="2.05"/>
  </joint>
  <joint name="joint3_1" type="revolute">
    <parent link="link2_1"/>
    <child link="link3_1"/>
    <origin xyz="0.0 0.035 0.205" rpy="0.0 -0.0 0.0"/>
    <axis xyz="0.0 0.0 1.0"/>
    <limit effort="64.0" velocity="2.4435" lower="-2.75" upper="2.75"/>
  </joint>
  <joint name="joint4_1" type="revolute">
    <parent link="link3_1"/>
    <child link="link4_1"/>
    <origin xyz="-0.02 -0.03 0.19" rpy="0.0 -0.0 -3.141592653589793"/>
    <axis xyz="0.0 1.0 0.0"/>
    <limit effort="64.0" velocity="2.4435" lower="-1.64" upper="2.47"/>
  </joint>
  <joint name="joint5_1" type="revolute">
    <parent link="link4_1"/>
    <child link="link5_1"/>
    <origin xyz="-0.02 0.025 0.195" rpy="0.0 -0.0 -3.141592653589793"/>
    <axis xyz="0.0 0.0 1.0"/>
    <limit effort="39.0" velocity="4.8869" lower="-2.77" upper="2.77"/>
  </joint>
  <joint name="joint6_1" type="revolute">
    <parent link="link5_1"/>
    <child link="link6_1"/>
    <origin xyz="0.0 0.03 0.19" rpy="0.0 -0.0 0.0"/>
    <axis xyz="0.0 1.0 0.0"/>
    <limit effort="39.0" velocity="4.8869" lower="-1.21" upper="4.35"/>
  </joint>
  <joint name="joint7_1" type="revolute">
    <parent link="link6_1"/>
    <child link="link7_1"/>
    <origin xyz="-0.055 0.07 0.11" rpy="-0.0 -1.5707963267948966 0.0"/>
    <axis xyz="0.0 0.0 1.0"/>
    <limit effort="39.0" velocity="4.8869" lower="-2.77" upper="2.77"/>
  </joint>
  <joint name="link7_to_flange_1" type="fixed">
    <parent link="link7_1"/>
    <child link="flange_1"/>
    <origin xyz="0.0 0.0 0.081" rpy="0.0 -0.0 -3.141592653589793"/>
    <axis xyz="1.0 0.0 0.0"/>
  </joint>
  <joint name="flange_ee_fixed" type="fixed">
    <parent link="flange"/>
    <child link="ee_target"/>
    <origin xyz="0.0 0.0 0.17" rpy="0.0 -0.0 0.0"/>
    <axis xyz="1.0 0.0 0.0"/>
  </joint>
  <joint name="flange_ee_fixed_1" type="fixed">
    <parent link="flange_1"/>
    <child link="ee_target_1"/>
    <origin xyz="0.0 0.0 0.17" rpy="0.0 -0.0 0.0"/>
    <axis xyz="1.0 0.0 0.0"/>
  </joint>
</robot>
